<?xml version="1.0" encoding="utf-8"?>
<!-- This URDF was automatically created by SolidWorks to URDF Exporter! Originally created by
Stephen Brawner (brawner@gmail.com) 
     Commit Version: 1.6.0-4-g7f85cfe  Build Version: 1.6.7995.38578
     For more information, please see http://wiki.ros.org/sw_urdf_exporter -->
<robot name="arm_robot" xmlns:xacro="http://www.ros.org/wiki/xacro">

    <xacro:arg name="arm_prefix" default="" />

	<link name="$(arg arm_prefix)base"></link>

	<joint name="$(arg arm_prefix)base_joint" type="fixed">
        <origin xyz="0.04 -0.05 0.1" rpy="-1.5707 0 0" />
        <parent link="$(arg arm_prefix)base" />
        <child link="$(arg arm_prefix)base_link" />
	</joint>

    <link name="$(arg arm_prefix)base_link">
        <inertial>
            <origin xyz="-0.1344 0.0501 -0.0978" rpy="0 0 0" />
            <mass value="0.543" />
            <inertia 
                ixx="0.00144"
                ixy="0.00001"
                ixz="0.00000"
                iyy="0.00143"
                iyz="0.00000"
                izz="0.00276" />
        </inertial>
        <visual>
            <origin xyz="0 0 0" rpy="0 0 0" />
            <geometry>
                <mesh filename="file:///$(find aero_description)/meshes/arm_base_link.stl" />
            </geometry>
            <material name="">
                <color rgba="0.492 0.520 0.633 1" />
            </material>
        </visual>
        <collision>
            <origin xyz="0 0 0" rpy="0 0 0" />
            <geometry>
                <mesh filename="file:///$(find aero_description)/meshes/arm_base_link.stl" />
            </geometry>
        </collision>
    </link>

    <link name="$(arg arm_prefix)LINK1">
        <inertial>
            <origin xyz="-0.0071 0.0135 0.0925" rpy="0 0 0" />
            <mass value="0.903" />
            <inertia 
                ixx="0.00087"
                ixy="-0.00013"
                ixz="-0.00002"
                iyy="0.00121"
                iyz="-0.00001"
                izz="0.00112" />
        </inertial>
        <visual>
            <origin xyz="0 0 0" rpy="0 0 0" />
            <geometry>
                <mesh filename="file:///$(find aero_description)/meshes/LINK1.stl" />
            </geometry>
            <material name="">
                <color rgba="0.792 0.820 0.933 1" />
            </material>
        </visual>
        <collision>
            <origin xyz="0 0 0" rpy="0 0 0" />
            <geometry>
                <mesh filename="file:///$(find aero_description)/meshes/LINK1.stl" />
            </geometry>
        </collision>
    </link>

    <joint name="$(arg arm_prefix)joint0" type="revolute">
        <origin xyz="-0.1136 0.1021 0.0440" rpy="1.571 0 0" />
        <parent link="$(arg arm_prefix)base_link" />
        <child link="$(arg arm_prefix)LINK1" />
        <axis xyz="0 0 1" />
        <!-- <limit lower="-3.14" upper="3.14" effort="10" velocity="1" /> -->
        <limit lower="-3.14" upper="3.14" effort="100" velocity="100" />
    </joint>

    <link name="$(arg arm_prefix)LINK2">
        <inertial>
            <origin xyz="0.1108 0.0375 0.4062" rpy="0 0 0" />
            <mass value="0.3638" />
            <inertia 
                ixx="0.00069"
                ixy="0.00003"
                ixz="-0.00008"
                iyy="0.00061"
                iyz="-0.00003"
                izz="0.00033" />
        </inertial>
        <visual>
            <origin xyz="0 0 0" rpy="0 0 0" />
            <geometry>
                <mesh filename="file:///$(find aero_description)/meshes/LINK2.stl" />
            </geometry>
            <material name="">
                <color rgba="0.492 0.520 0.633 1" />
            </material>
        </visual>
        <collision>
            <origin xyz="0 0 0" rpy="0 0 0" />
            <geometry>
                <mesh filename="file:///$(find aero_description)/meshes/LINK2.stl" />
            </geometry>
        </collision>
    </link>

    <joint name="$(arg arm_prefix)joint1" type="revolute">
        <origin xyz="0.0005 0.0164 0.1485" rpy="0.0135 0.0042 0.0520" />
        <parent link="$(arg arm_prefix)LINK1" />
        <child link="$(arg arm_prefix)LINK2" />
        <axis xyz="0.249 0.0848 0.9648" />
        <!-- <axis xyz="0.0211 -0.9928 0.0817" /> -->
        <!-- <limit lower="-1.57" upper="1.57" effort="10" velocity="1" /> -->
        <limit lower="-1.57" upper="1.57" effort="100" velocity="100" />
    </joint>

    <link name="$(arg arm_prefix)LINK3">
        <inertial>
            <origin xyz="0.0544 0.0183 -0.0847" rpy="0 0 0" />
            <mass value="0.4096" />
            <inertia 
                ixx="0.00047"
                ixy="0.00002"
                ixz="0.00021"
                iyy="0.00061"
                iyz="-0.00002"
                izz="0.00041" />
        </inertial>
        <visual>
            <origin xyz="0 0 0" rpy="0 0 0" />
            <geometry>
                <mesh filename="file:///$(find aero_description)/meshes/LINK3.stl" />
            </geometry>
            <material name="">
                <color rgba="0.792 0.820 0.933 1" />
            </material>
        </visual>
        <collision>
            <origin xyz="0 0 0" rpy="0 0 0" />
            <geometry>
                <mesh filename="file:///$(find aero_description)/meshes/LINK3.stl" />
            </geometry>
        </collision>
    </link>

    <joint name="$(arg arm_prefix)joint2" type="revolute">
        <origin xyz="0.2719 0.0926 0.2077" rpy="0.0187 0.0066 -0.0273" />
        <parent link="$(arg arm_prefix)LINK2" />
        <child link="$(arg arm_prefix)LINK3" />
        <!-- <axis xyz="0.107 -0.982 -0.156" /> -->
        <axis xyz="0.5547 0.1889 -0.8103" />
        <!-- <limit lower="-1.57" upper="1.57" effort="10" velocity="1" /> -->
        <limit lower="-1.57" upper="1.57" effort="100" velocity="100" />
    </joint>

    <link name="$(arg arm_prefix)LINK4">
        <inertial>
            <origin xyz="0.0233 0.0079 -0.0131" rpy="0 0 0" />
            <mass value="0.1682" />
            <inertia 
                ixx="0.00016"
                ixy="0.00002"
                ixz="-0.00002"
                iyy="0.00012"
                iyz="-0.00001"
                izz="0.00013" />
        </inertial>
        <visual>
            <origin xyz="0 0 0" rpy="0 0 0" />
            <geometry>
                <mesh filename="file:///$(find aero_description)/meshes/LINK4.stl" />
            </geometry>
            <material name="">
                <color rgba="0.492 0.520 0.633 1" />
            </material>
        </visual>
        <collision>
            <origin xyz="0 0 0" rpy="0 0 0" />
            <geometry>
                <mesh filename="file:///$(find aero_description)/meshes/LINK4.stl" />
            </geometry>
        </collision>
    </link>

    <link name="$(arg arm_prefix)tool_link"> </link>

    <joint name="$(arg arm_prefix)tool_joint" type="fixed">
        <origin xyz= "0 0.1 0" rpy="0 0 0" />
        <parent link="$(arg arm_prefix)end" />
        <child link="$(arg arm_prefix)tool_link" />
    </joint>

    <joint name="$(arg arm_prefix)joint3" type="revolute">
        <origin xyz="0.1127 0.0384 -0.1402" rpy="-0.0155 -0.0052 0.0087" />
        <parent link="$(arg arm_prefix)LINK3" />
        <child link="$(arg arm_prefix)LINK4" />
        <axis xyz="0.8360 0.2848 -0.4691" />
        <!-- <limit lower="-1.57" upper="1.57" effort="10" velocity="1" /> -->
        <limit lower="-1.57" upper="1.57" effort="100" velocity="100" />
    </joint>

    <link name="$(arg arm_prefix)end">
        <inertial>
            <origin xyz="0.0000 0.0890 0.0000" rpy="0 0 0" />
            <mass value="0.2565" />
            <inertia 
                ixx="0.00009"
                ixy="0.00000"
                ixz="0.00000"
                iyy="0.00013"
                iyz="0.00000"
                izz="0.00013" />
        </inertial>
        <visual>
            <origin xyz="0 0 0" rpy="0 0 0" />
            <geometry>
                <mesh filename="file:///$(find aero_description)/meshes/arm_end.stl" />
            </geometry>
            <material name="">
                <color rgba="0.792 0.820 0.933 1" />
            </material>
        </visual>
        <collision>
            <origin xyz="0 0 0" rpy="0 0 0" />
            <geometry>
                <mesh filename="file:///$(find aero_description)/meshes/arm_end.stl" />
            </geometry>
        </collision>
    </link>

    <joint name="$(arg arm_prefix)joint4" type="fixed">
        <origin xyz="0 0 0" rpy="-0.5158 -0.3142 -1.0690" />
        <parent link="$(arg arm_prefix)LINK4" />
        <child link="$(arg arm_prefix)end" />
        <!-- <axis xyz="0 1 0" /> -->
    </joint>
</robot>